Workbook

Sheet Calculadora
A1: w
C2: CALCULADORA GENESIS COMMUNITY V3 | L2: PLANTILLA TUNEOS
L3: ="Matrícula: " & TEXT(C30, "") -> Matrícula:
C4: MODELO | E4: CATEGORÍA | H4: PRESUPUESTO | L4: ="Modelo: " & TEXT(C6 , "") -> Modelo: Shinobi
C5: shinobi | E5: =VLOOKUP(C5,Listado!A:F,4,FALSE) -> Motos | H5: MOTOR | J5: =IF(D11, E7*0.15, 0) + IF(D11, 300, 0) -> 0 | L5: ="Modificación: " & IF(D7, "Full Tuning", IF(D11, "Motor", "") & IF(D13>0, "+ Performance (" & D13 & " piezas) ", "") & IF(D15>0, "+ Custom (" & D15 & " piezas) ", "") & IF(D17>0, "+ Cosmetic (" & D17 & " piezas) ", "") ) & IF(D9, "+ Pintura camaleónica ", "") & IF(D20, "+ Reparación", "") -> Modificación:
C6: =VLOOKUP(C5,Listado!A:F,2,FALSE) -> Shinobi | E6: <-- NOMBRE IC | H6: PERFORMANCE | J6: =IF(D13>0, E7*0.15, 0) + D13*200 -> 0 | L6: ="Importe: " & TEXT(J9, "#$") -> Importe: $
C7: FULL TUNNING | D7: FALSE | E7: =VLOOKUP(C5,Listado!A:F,3,FALSE) -> 100000 | H7: CUSTOM | J7: =IF(D15>0, E7*0.05, 0) + D15*100 -> 0 | L7: ="Empleado que realizo el servicio: " & TEXT(C27 , "") -> Empleado que realizo el servicio:
H8: COSMETIC | J8: =IF(D17>0, E7*0.05, 0) + D17*50 -> 0 | L8: ="Convenio y descuento: " & I16 & " (" & I13 & "%)" -> Convenio y descuento: N/A (0%)
C9: PINTURA CAMALEÓNICA | D9: FALSE | E9: MECÁNICA | H9: PRECIO TOTAL | J9: =IF(E5="VIP", IF(D7, 5000 + IF(D11,300,0) + D13*200 + D15*100 + D17*50 + IF(D20,D24,0), IF(D11,1000,0) + D13*1000 + D15*1000 + D17*1000 + IF(D20,D24,0) ), IF(D7, (E7*0.4)*(1-(I13/100)) + IF(D20,D24,0), ( IF(D11,E7*0.15,0) + IF(D13>0,E7*0.15,0) + IF(D15>0,E7*0.05,0) + IF(D17>0,E7*0.05,0) + IF(D11,300,0) + D13*200 + D15*100 + D17*50 )*(1-(I13/100)) + IF(D20,D24,0) ) )+ IF(D9, 5000, 0) -> 0
C10: MOTOR | E10: PIEZAS
C11: PIEZAS | D11: FALSE | E11: FULL | F11: FALSE | L11: PLANTILLA REPARACIONES
C12: PERFORMANCE | H12: DESCUENTO (%) | L12: ="Matrícula: " & TEXT(C30, "") -> Matrícula:
C13: PIEZAS | D13: 0 | H13: PORCENTAJE | I13: 0 | L13: ="Modelo: " & TEXT(C6 , "") -> Modelo: Shinobi
C14: CUSTOM | L14: ="Modificación: Reparación" -> Modificación: Reparación
C15: PIEZAS | D15: 0 | H15: NEGOCIOS | L15: ="Importe: " & TEXT(D24, "#$") -> Importe: $
C16: COSMETIC | H16: NEGOCIOS | I16: N/A | L16: ="Empleado que realizo el servicio: " & TEXT(C27 , "") -> Empleado que realizo el servicio:
C17: PIEZAS | D17: 0 | L17: ="Convenio y descuento: " & I16 & " (" & I13 & "%)" -> Convenio y descuento: N/A (0%)
C20: REPARACIÓN | D20: FALSE
C21: Partes del chasis | D21: 0
C22: Partes esenciales | D22: 0 | H22: =IFERROR(IMAGE(VLOOKUP(C6,Listado!A:E,5,FALSE)), "No hay imagen para este vehículo")
C23: Partes de servicio | D23: 0
C24: PRECIO TOTAL | D24: =((D21*30) + (D22*65) + (D23*40)) * (1 - I13/100) -> 0
C26: NOMBRE DEL MECÁNICO
C29: Matrícula
H37: =IFERROR(IMAGE(VLOOKUP(C26,Listado!A:E,5,FALSE)), "No hay imagen para este vehículo") -> No hay imagen para este vehículo
H52: =IFERROR(IMAGE(VLOOKUP(C39,Listado!A:E,5,FALSE)), "No hay imagen para este vehículo") -> No hay imagen para este vehículo
H67: =IFERROR(IMAGE(VLOOKUP(C54,Listado!A:E,5,FALSE)), "No hay imagen para este vehículo") -> No hay imagen para este vehículo
H82: =IFERROR(IMAGE(VLOOKUP(C69,Listado!A:E,5,FALSE)), "No hay imagen para este vehículo") -> No hay imagen para este vehículo
H97: =IFERROR(IMAGE(VLOOKUP(C84,Listado!A:E,5,FALSE)), "No hay imagen para este vehículo") -> No hay imagen para este vehículo
H112: =IFERROR(IMAGE(VLOOKUP(C99,Listado!A:E,5,FALSE)), "No hay imagen para este vehículo") -> No hay imagen para este vehículo
H127: =IFERROR(IMAGE(VLOOKUP(C114,Listado!A:E,5,FALSE)), "No hay imagen para este vehículo") -> No hay imagen para este vehículo
H142: =IFERROR(IMAGE(VLOOKUP(C129,Listado!A:E,5,FALSE)), "No hay imagen para este vehículo") -> No hay imagen para este vehículo
H157: =IFERROR(IMAGE(VLOOKUP(C144,Listado!A:E,5,FALSE)), "No hay imagen para este vehículo") -> No hay imagen para este vehículo
H172: =IFERROR(IMAGE(VLOOKUP(C159,Listado!A:E,5,FALSE)), "No hay imagen para este vehículo") -> No hay imagen para este vehículo
H187: =IFERROR(IMAGE(VLOOKUP(C174,Listado!A:E,5,FALSE)), "No hay imagen para este vehículo") -> No hay imagen para este vehículo
H202: =IFERROR(IMAGE(VLOOKUP(C189,Listado!A:E,5,FALSE)), "No hay imagen para este vehículo") -> No hay imagen para este vehículo
H217: =IFERROR(IMAGE(VLOOKUP(C204,Listado!A:E,5,FALSE)), "No hay imagen para este vehículo") -> No hay imagen para este vehículo

Sheet Listado
A1: Modelo | B1: Nombre | C1: Precio | D1: Categoría | E1: FOTOS
A2: =IFERROR(__xludf.DUMMYFUNCTION("IMPORTRANGE(""https://docs.google.com/spreadsheets/d/1mjNNDGrvmUts6VjAqwo43L28lC7JMK2L6g8bGEhk9BI/edit?gid=1084388773#gid=1084388773"", ""A2:E990"")"),"bmx") -> bmx | B2: =IFERROR(__xludf.DUMMYFUNCTION("""COMPUTED_VALUE"""),"BMX") -> BMX | C2: =IFERROR(__xludf.DUMMYFUNCTION("""COMPUTED_VALUE"""),1500.0) -> 1500 | D2: =IFERROR(__xludf.DUMMYFUNCTION("""COMPUTED_VALUE"""),"Bicicletas") -> Bicicletas | E2: =IFERROR(__xludf.DUMMYFUNCTION("""COMPUTED_VALUE"""),"https://docs.fivem.net/vehicles/bmx.webp") -> https://docs.fivem.net/vehicles/bmx.webp
A3: =IFERROR(__xludf.DUMMYFUNCTION("""COMPUTED_VALUE"""),"cruiser") -> cruiser | B3: =IFERROR(__xludf.DUMMYFUNCTION("""COMPUTED_VALUE"""),"Cruiser") -> Cruiser | C3: =IFERROR(__xludf.DUMMYFUNCTION("""COMPUTED_VALUE"""),1000.0) -> 1000 | D3: =IFERROR(__xludf.DUMMYFUNCTION("""COMPUTED_VALUE"""),"Bicicletas") -> Bicicletas | E3: =IFERROR(__xludf.DUMMYFUNCTION("""COMPUTED_VALUE"""),"https://docs.fivem.net/vehicles/cruiser.webp") -> https://docs.fivem.net/vehicles/cruiser.webp
A4: =IFERROR(__xludf.DUMMYFUNCTION("""COMPUTED_VALUE"""),"fixter") -> fixter | B4: =IFERROR(__xludf.DUMMYFUNCTION("""COMPUTED_VALUE"""),"Fixter") -> Fixter | C4: =IFERROR(__xludf.DUMMYFUNCTION("""COMPUTED_VALUE"""),1200.0) -> 1200 | D4: =IFERROR(__xludf.DUMMYFUNCTION("""COMPUTED_VALUE"""),"Bicicletas") -> Bicicletas | E4: =IFERROR(__xludf.DUMMYFUNCTION("""COMPUTED_VALUE"""),"https://docs.fivem.net/vehicles/fixter.webp") -> https://docs.fivem.net/vehicles/fixter.webp
A5: =IFERROR(__xludf.DUMMYFUNCTION("""COMPUTED_VALUE"""),"inductor") -> inductor | B5: =IFERROR(__xludf.DUMMYFUNCTION("""COMPUTED_VALUE"""),"Inductor") -> Inductor | C5: =IFERROR(__xludf.DUMMYFUNCTION("""COMPUTED_VALUE"""),7500.0) -> 7500 | D5: =IFERROR(__xludf.DUMMYFUNCTION("""COMPUTED_VALUE"""),"Bicicletas") -> Bicicletas | E5: =IFERROR(__xludf.DUMMYFUNCTION("""COMPUTED_VALUE"""),"https://docs.fivem.net/vehicles/inductor.webp") -> https://docs.fivem.net/vehicles/inductor.webp
A6: =IFERROR(__xludf.DUMMYFUNCTION("""COMPUTED_VALUE"""),"inductor2") -> inductor2 | B6: =IFERROR(__xludf.DUMMYFUNCTION("""COMPUTED_VALUE"""),"Junk Energy Inductor") -> Junk Energy Inductor | C6: =IFERROR(__xludf.DUMMYFUNCTION("""COMPUTED_VALUE"""),8200.0) -> 8200 | D6: =IFERROR(__xludf.DUMMYFUNCTION("""COMPUTED_VALUE"""),"Bicicletas") -> Bicicletas | E6: =IFERROR(__xludf.DUMMYFUNCTION("""COMPUTED_VALUE"""),"https://docs.fivem.net/vehicles/inductor2.webp") -> https://docs.fivem.net/vehicles/inductor2.webp
A7: =IFERROR(__xludf.DUMMYFUNCTION("""COMPUTED_VALUE"""),"scorcher") -> scorcher | B7: =IFERROR(__xludf.DUMMYFUNCTION("""COMPUTED_VALUE"""),"Scorcher") -> Scorcher | C7: =IFERROR(__xludf.DUMMYFUNCTION("""COMPUTED_VALUE"""),2000.0) -> 2000 | D7: =IFERROR(__xludf.DUMMYFUNCTION("""COMPUTED_VALUE"""),"Bicicletas") -> Bicicletas | E7: =IFERROR(__xludf.DUMMYFUNCTION("""COMPUTED_VALUE"""),"https://docs.fivem.net/vehicles/scorcher.webp") -> https://docs.fivem.net/vehicles/scorcher.webp
A8: =IFERROR(__xludf.DUMMYFUNCTION("""COMPUTED_VALUE"""),"tribike") -> tribike | B8: =IFERROR(__xludf.DUMMYFUNCTION("""COMPUTED_VALUE"""),"Whippet Race Bike") -> Whippet Race Bike | C8: =IFERROR(__xludf.DUMMYFUNCTION("""COMPUTED_VALUE"""),1700.0) -> 1700 | D8: =IFERROR(__xludf.DUMMYFUNCTION("""COMPUTED_VALUE"""),"Bicicletas") -> Bicicletas | E8: =IFERROR(__xludf.DUMMYFUNCTION("""COMPUTED_VALUE"""),"https://docs.fivem.net/vehicles/tribike.webp") -> https://docs.fivem.net/vehicles/tribike.webp
A9: =IFERROR(__xludf.DUMMYFUNCTION("""COMPUTED_VALUE"""),"tribike2") -> tribike2 | B9: =IFERROR(__xludf.DUMMYFUNCTION("""COMPUTED_VALUE"""),"Endurex Race Bike") -> Endurex Race Bike | C9: =IFERROR(__xludf.DUMMYFUNCTION("""COMPUTED_VALUE"""),1700.0) -> 1700 | D9: =IFERROR(__xludf.DUMMYFUNCTION("""COMPUTED_VALUE"""),"Bicicletas") -> Bicicletas | E9: =IFERROR(__xludf.DUMMYFUNCTION("""COMPUTED_VALUE"""),"https://docs.fivem.net/vehicles/tribike2.webp") -> https://docs.fivem.net/vehicles/tribike2.webp
A10: =IFERROR(__xludf.DUMMYFUNCTION("""COMPUTED_VALUE"""),"tribike3") -> tribike3 | B10: =IFERROR(__xludf.DUMMYFUNCTION("""COMPUTED_VALUE"""),"Tri-cycle Race Bike") -> Tri-cycle Race Bike | C10: =IFERROR(__xludf.DUMMYFUNCTION("""COMPUTED_VALUE"""),1800.0) -> 1800 | D10: =IFERROR(__xludf.DUMMYFUNCTION("""COMPUTED_VALUE"""),"Bicicletas") -> Bicicletas | E10: =IFERROR(__xludf.DUMMYFUNCTION("""COMPUTED_VALUE"""),"https://docs.fivem.net/vehicles/tribike3.webp") -> https://docs.fivem.net/vehicles/tribike3.webp
A11: =IFERROR(__xludf.DUMMYFUNCTION("""COMPUTED_VALUE"""),"formula") -> formula | B11: =IFERROR(__xludf.DUMMYFUNCTION("""COMPUTED_VALUE"""),"PR4") -> PR4 | C11: =IFERROR(__xludf.DUMMYFUNCTION("""COMPUTED_VALUE"""),1000000.0) -> 1000000 | D11: =IFERROR(__xludf.DUMMYFUNCTION("""COMPUTED_VALUE"""),"Circuitos") -> Circuitos | E11: =IFERROR(__xludf.DUMMYFUNCTION("""COMPUTED_VALUE"""),"https://docs.fivem.net/vehicles/formula.webp") -> https://docs.fivem.net/vehicles/formula.webp
A12: =IFERROR(__xludf.DUMMYFUNCTION("""COMPUTED_VALUE"""),"formula2") -> formula2 | B12: =IFERROR(__xludf.DUMMYFUNCTION("""COMPUTED_VALUE"""),"R88") -> R88 | C12: =IFERROR(__xludf.DUMMYFUNCTION("""COMPUTED_VALUE"""),1000000.0) -> 1000000 | D12: =IFERROR(__xludf.DUMMYFUNCTION("""COMPUTED_VALUE"""),"Circuitos") -> Circuitos | E12: =IFERROR(__xludf.DUMMYFUNCTION("""COMPUTED_VALUE"""),"https://docs.fivem.net/vehicles/formula2.webp") -> https://docs.fivem.net/vehicles/formula2.webp
A13: =IFERROR(__xludf.DUMMYFUNCTION("""COMPUTED_VALUE"""),"openwheel1") -> openwheel1 | B13: =IFERROR(__xludf.DUMMYFUNCTION("""COMPUTED_VALUE"""),"BR8") -> BR8 | C13: =IFERROR(__xludf.DUMMYFUNCTION("""COMPUTED_VALUE"""),2000000.0) -> 2000000 | D13: =IFERROR(__xludf.DUMMYFUNCTION("""COMPUTED_VALUE"""),"Circuitos") -> Circuitos | E13: =IFERROR(__xludf.DUMMYFUNCTION("""COMPUTED_VALUE"""),"https://docs.fivem.net/vehicles/openwheel1.webp") -> https://docs.fivem.net/vehicles/openwheel1.webp
A14: =IFERROR(__xludf.DUMMYFUNCTION("""COMPUTED_VALUE"""),"openwheel2") -> openwheel2 | B14: =IFERROR(__xludf.DUMMYFUNCTION("""COMPUTED_VALUE"""),"DR1") -> DR1 | C14: =IFERROR(__xludf.DUMMYFUNCTION("""COMPUTED_VALUE"""),1500000.0) -> 1500000 | D14: =IFERROR(__xludf.DUMMYFUNCTION("""COMPUTED_VALUE"""),"Circuitos") -> Circuitos | E14: =IFERROR(__xludf.DUMMYFUNCTION("""COMPUTED_VALUE"""),"https://docs.fivem.net/vehicles/openwheel2.webp") -> https://docs.fivem.net/vehicles/openwheel2.webp
A15: =IFERROR(__xludf.DUMMYFUNCTION("""COMPUTED_VALUE"""),"asbo") -> asbo | B15: =IFERROR(__xludf.DUMMYFUNCTION("""COMPUTED_VALUE"""),"Asbo") -> Asbo | C15: =IFERROR(__xludf.DUMMYFUNCTION("""COMPUTED_VALUE"""),2500.0) -> 2500 | D15: =IFERROR(__xludf.DUMMYFUNCTION("""COMPUTED_VALUE"""),"Compactos") -> Compactos | E15: =IFERROR(__xludf.DUMMYFUNCTION("""COMPUTED_VALUE"""),"https://docs.fivem.net/vehicles/asbo.webp") -> https://docs.fivem.net/vehicles/asbo.webp
A16: =IFERROR(__xludf.DUMMYFUNCTION("""COMPUTED_VALUE"""),"blista") -> blista | B16: =IFERROR(__xludf.DUMMYFUNCTION("""COMPUTED_VALUE"""),"Blista") -> Blista | C16: =IFERROR(__xludf.DUMMYFUNCTION("""COMPUTED_VALUE"""),4000.0) -> 4000 | D16: =IFERROR(__xludf.DUMMYFUNCTION("""COMPUTED_VALUE"""),"Compactos") -> Compactos | E16: =IFERROR(__xludf.DUMMYFUNCTION("""COMPUTED_VALUE"""),"https://docs.fivem.net/vehicles/blista.webp") -> https://docs.fivem.net/vehicles/blista.webp
A17: =IFERROR(__xludf.DUMMYFUNCTION("""COMPUTED_VALUE"""),"blista2") -> blista2 | B17: =IFERROR(__xludf.DUMMYFUNCTION("""COMPUTED_VALUE"""),"Blista Compact") -> Blista Compact | C17: =IFERROR(__xludf.DUMMYFUNCTION("""COMPUTED_VALUE"""),15000.0) -> 15000 | D17: =IFERROR(__xludf.DUMMYFUNCTION("""COMPUTED_VALUE"""),"Compactos") -> Compactos | E17: =IFERROR(__xludf.DUMMYFUNCTION("""COMPUTED_VALUE"""),"https://docs.fivem.net/vehicles/blista2.webp") -> https://docs.fivem.net/vehicles/blista2.webp
A18: =IFERROR(__xludf.DUMMYFUNCTION("""COMPUTED_VALUE"""),"blista3") -> blista3 | B18: =IFERROR(__xludf.DUMMYFUNCTION("""COMPUTED_VALUE"""),"Blista Go Go Monkey") -> Blista Go Go Monkey | C18: =IFERROR(__xludf.DUMMYFUNCTION("""COMPUTED_VALUE"""),15000.0) -> 15000 | D18: =IFERROR(__xludf.DUMMYFUNCTION("""COMPUTED_VALUE"""),"Compactos") -> Compactos | E18: =IFERROR(__xludf.DUMMYFUNCTION("""COMPUTED_VALUE"""),"https://docs.fivem.net/vehicles/blista3.webp") -> https://docs.fivem.net/vehicles/blista3.webp
A19: =IFERROR(__xludf.DUMMYFUNCTION("""COMPUTED_VALUE"""),"boor") -> boor | B19: =IFERROR(__xludf.DUMMYFUNCTION("""COMPUTED_VALUE"""),"Boor") -> Boor | C19: =IFERROR(__xludf.DUMMYFUNCTION("""COMPUTED_VALUE"""),13500.0) -> 13500 | D19: =IFERROR(__xludf.DUMMYFUNCTION("""COMPUTED_VALUE"""),"Compactos") -> Compactos | E19: =IFERROR(__xludf.DUMMYFUNCTION("""COMPUTED_VALUE"""),"https://docs.fivem.net/vehicles/boor.webp") -> https://docs.fivem.net/vehicles/boor.webp
A20: =IFERROR(__xludf.DUMMYFUNCTION("""COMPUTED_VALUE"""),"brioso") -> brioso | B20: =IFERROR(__xludf.DUMMYFUNCTION("""COMPUTED_VALUE"""),"Brioso R/A") -> Brioso R/A | C20: =IFERROR(__xludf.DUMMYFUNCTION("""COMPUTED_VALUE"""),13500.0) -> 13500 | D20: =IFERROR(__xludf.DUMMYFUNCTION("""COMPUTED_VALUE"""),"Compactos") -> Compactos | E20: =IFERROR(__xludf.DUMMYFUNCTION("""COMPUTED_VALUE"""),"https://docs.fivem.net/vehicles/lectro.webp") -> https://docs.fivem.net/vehicles/lectro.webp
A21: =IFERROR(__xludf.DUMMYFUNCTION("""COMPUTED_VALUE"""),"brioso2") -> brioso2 | B21: =IFERROR(__xludf.DUMMYFUNCTION("""COMPUTED_VALUE"""),"Brioso 300") -> Brioso 300 | C21: =IFERROR(__xludf.DUMMYFUNCTION("""COMPUTED_VALUE"""),4500.0) -> 4500 | D21: =IFERROR(__xludf.DUMMYFUNCTION("""COMPUTED_VALUE"""),"Compactos") -> Compactos | E21: =IFERROR(__xludf.DUMMYFUNCTION("""COMPUTED_VALUE"""),"https://docs.fivem.net/vehicles/brioso2.webp") -> https://docs.fivem.net/vehicles/brioso2.webp
A22: =IFERROR(__xludf.DUMMYFUNCTION("""COMPUTED_VALUE"""),"club") -> club | B22: =IFERROR(__xludf.DUMMYFUNCTION("""COMPUTED_VALUE"""),"Club") -> Club | C22: =IFERROR(__xludf.DUMMYFUNCTION("""COMPUTED_VALUE"""),12500.0) -> 12500 | D22: =IFERROR(__xludf.DUMMYFUNCTION("""COMPUTED_VALUE"""),"Compactos") -> Compactos | E22: =IFERROR(__xludf.DUMMYFUNCTION("""COMPUTED_VALUE"""),"https://docs.fivem.net/vehicles/club.webp") -> https://docs.fivem.net/vehicles/club.webp
A23: =IFERROR(__xludf.DUMMYFUNCTION("""COMPUTED_VALUE"""),"dilettante") -> dilettante | B23: =IFERROR(__xludf.DUMMYFUNCTION("""COMPUTED_VALUE"""),"Dilettante") -> Dilettante | C23: =IFERROR(__xludf.DUMMYFUNCTION("""COMPUTED_VALUE"""),9000.0) -> 9000 | D23: =IFERROR(__xludf.DUMMYFUNCTION("""COMPUTED_VALUE"""),"Compactos") -> Compactos | E23: =IFERROR(__xludf.DUMMYFUNCTION("""COMPUTED_VALUE"""),"https://docs.fivem.net/vehicles/dilettante.webp") -> https://docs.fivem.net/vehicles/dilettante.webp
A24: =IFERROR(__xludf.DUMMYFUNCTION("""COMPUTED_VALUE"""),"issi2") -> issi2 | B24: =IFERROR(__xludf.DUMMYFUNCTION("""COMPUTED_VALUE"""),"Issi") -> Issi | C24: =IFERROR(__xludf.DUMMYFUNCTION("""COMPUTED_VALUE"""),7000.0) -> 7000 | D24: =IFERROR(__xludf.DUMMYFUNCTION("""COMPUTED_VALUE"""),"Compactos") -> Compactos | E24: =IFERROR(__xludf.DUMMYFUNCTION("""COMPUTED_VALUE"""),"https://docs.fivem.net/vehicles/issi2.webp") -> https://docs.fivem.net/vehicles/issi2.webp
A25: =IFERROR(__xludf.DUMMYFUNCTION("""COMPUTED_VALUE"""),"issi3") -> issi3 | B25: =IFERROR(__xludf.DUMMYFUNCTION("""COMPUTED_VALUE"""),"Issi Classic") -> Issi Classic | C25: =IFERROR(__xludf.DUMMYFUNCTION("""COMPUTED_VALUE"""),3900.0) -> 3900 | D25: =IFERROR(__xludf.DUMMYFUNCTION("""COMPUTED_VALUE"""),"Compactos") -> Compactos | E25: =IFERROR(__xludf.DUMMYFUNCTION("""COMPUTED_VALUE"""),"https://docs.fivem.net/vehicles/issi3.webp") -> https://docs.fivem.net/vehicles/issi3.webp
A26: =IFERROR(__xludf.DUMMYFUNCTION("""COMPUTED_VALUE"""),"issi4") -> issi4 | B26: =IFERROR(__xludf.DUMMYFUNCTION("""COMPUTED_VALUE"""),"Issi Arena") -> Issi Arena | C26: =IFERROR(__xludf.DUMMYFUNCTION("""COMPUTED_VALUE"""),61000.0) -> 61000 | D26: =IFERROR(__xludf.DUMMYFUNCTION("""COMPUTED_VALUE"""),"Compactos") -> Compactos | E26: =IFERROR(__xludf.DUMMYFUNCTION("""COMPUTED_VALUE"""),"https://docs.fivem.net/vehicles/issi4.webp") -> https://docs.fivem.net/vehicles/issi4.webp
A27: =IFERROR(__xludf.DUMMYFUNCTION("""COMPUTED_VALUE"""),"issi5") -> issi5 | B27: =IFERROR(__xludf.DUMMYFUNCTION("""COMPUTED_VALUE"""),"Issi Future Shock") -> Issi Future Shock | C27: =IFERROR(__xludf.DUMMYFUNCTION("""COMPUTED_VALUE"""),68500.0) -> 68500 | D27: =IFERROR(__xludf.DUMMYFUNCTION("""COMPUTED_VALUE"""),"Compactos") -> Compactos | E27: =IFERROR(__xludf.DUMMYFUNCTION("""COMPUTED_VALUE"""),"https://docs.fivem.net/vehicles/issi5.webp") -> https://docs.fivem.net/vehicles/issi5.webp
A28: =IFERROR(__xludf.DUMMYFUNCTION("""COMPUTED_VALUE"""),"issi6") -> issi6 | B28: =IFERROR(__xludf.DUMMYFUNCTION("""COMPUTED_VALUE"""),"Issi Nightmare") -> Issi Nightmare | C28: =IFERROR(__xludf.DUMMYFUNCTION("""COMPUTED_VALUE"""),70000.0) -> 70000 | D28: =IFERROR(__xludf.DUMMYFUNCTION("""COMPUTED_VALUE"""),"Compactos") -> Compactos | E28: =IFERROR(__xludf.DUMMYFUNCTION("""COMPUTED_VALUE"""),"https://docs.fivem.net/vehicles/issi6.webp") -> https://docs.fivem.net/vehicles/issi6.webp
A29: =IFERROR(__xludf.DUMMYFUNCTION("""COMPUTED_VALUE"""),"issi7") -> issi7 | B29: =IFERROR(__xludf.DUMMYFUNCTION("""COMPUTED_VALUE"""),"Issi Sport") -> Issi Sport | C29: =IFERROR(__xludf.DUMMYFUNCTION("""COMPUTED_VALUE"""),150000.0) -> 150000 | D29: =IFERROR(__xludf.DUMMYFUNCTION("""COMPUTED_VALUE"""),"Compactos") -> Compactos | E29: =IFERROR(__xludf.DUMMYFUNCTION("""COMPUTED_VALUE"""),"https://docs.fivem.net/vehicles/issi7.webp") -> https://docs.fivem.net/vehicles/issi7.webp
A30: =IFERROR(__xludf.DUMMYFUNCTION("""COMPUTED_VALUE"""),"issi8") -> issi8 | B30: =IFERROR(__xludf.DUMMYFUNCTION("""COMPUTED_VALUE"""),"Issi Rally") -> Issi Rally | C30: =IFERROR(__xludf.DUMMYFUNCTION("""COMPUTED_VALUE"""),140000.0) -> 140000 | D30: =IFERROR(__xludf.DUMMYFUNCTION("""COMPUTED_VALUE"""),"Compactos") -> Compactos | E30: =IFERROR(__xludf.DUMMYFUNCTION("""COMPUTED_VALUE"""),"https://docs.fivem.net/vehicles/issi8.webp") -> https://docs.fivem.net/vehicles/issi8.webp
A31: =IFERROR(__xludf.DUMMYFUNCTION("""COMPUTED_VALUE"""),"kanjo") -> kanjo | B31: =IFERROR(__xludf.DUMMYFUNCTION("""COMPUTED_VALUE"""),"Blista Kanjo") -> Blista Kanjo | C31: =IFERROR(__xludf.DUMMYFUNCTION("""COMPUTED_VALUE"""),12000.0) -> 12000 | D31: =IFERROR(__xludf.DUMMYFUNCTION("""COMPUTED_VALUE"""),"Compactos") -> Compactos | E31: =IFERROR(__xludf.DUMMYFUNCTION("""COMPUTED_VALUE"""),"https://docs.fivem.net/vehicles/kanjo.webp") -> https://docs.fivem.net/vehicles/kanjo.webp
A32: =IFERROR(__xludf.DUMMYFUNCTION("""COMPUTED_VALUE"""),"panto") -> panto | B32: =IFERROR(__xludf.DUMMYFUNCTION("""COMPUTED_VALUE"""),"Panto") -> Panto | C32: =IFERROR(__xludf.DUMMYFUNCTION("""COMPUTED_VALUE"""),9000.0) -> 9000 | D32: =IFERROR(__xludf.DUMMYFUNCTION("""COMPUTED_VALUE"""),"Compactos") -> Compactos | E32: =IFERROR(__xludf.DUMMYFUNCTION("""COMPUTED_VALUE"""),"https://docs.fivem.net/vehicles/panto.webp") -> https://docs.fivem.net/vehicles/panto.webp
A33: =IFERROR(__xludf.DUMMYFUNCTION("""COMPUTED_VALUE"""),"prairie") -> prairie | B33: =IFERROR(__xludf.DUMMYFUNCTION("""COMPUTED_VALUE"""),"Prairie") -> Prairie | C33: =IFERROR(__xludf.DUMMYFUNCTION("""COMPUTED_VALUE"""),8500.0) -> 8500 | D33: =IFERROR(__xludf.DUMMYFUNCTION("""COMPUTED_VALUE"""),"Compactos") -> Compactos | E33: =IFERROR(__xludf.DUMMYFUNCTION("""COMPUTED_VALUE"""),"https://docs.fivem.net/vehicles/prairie.webp") -> https://docs.fivem.net/vehicles/prairie.webp
A34: =IFERROR(__xludf.DUMMYFUNCTION("""COMPUTED_VALUE"""),"rhapsody") -> rhapsody | B34: =IFERROR(__xludf.DUMMYFUNCTION("""COMPUTED_VALUE"""),"Rhapsody") -> Rhapsody | C34: =IFERROR(__xludf.DUMMYFUNCTION("""COMPUTED_VALUE"""),12500.0) -> 12500 | D34: =IFERROR(__xludf.DUMMYFUNCTION("""COMPUTED_VALUE"""),"Compactos") -> Compactos | E34: =IFERROR(__xludf.DUMMYFUNCTION("""COMPUTED_VALUE"""),"https://docs.fivem.net/vehicles/rhapsody.webp") -> https://docs.fivem.net/vehicles/rhapsody.webp
A35: =IFERROR(__xludf.DUMMYFUNCTION("""COMPUTED_VALUE"""),"weevil") -> weevil | B35: =IFERROR(__xludf.DUMMYFUNCTION("""COMPUTED_VALUE"""),"Weevil") -> Weevil | C35: =IFERROR(__xludf.DUMMYFUNCTION("""COMPUTED_VALUE"""),4500.0) -> 4500 | D35: =IFERROR(__xludf.DUMMYFUNCTION("""COMPUTED_VALUE"""),"Compactos") -> Compactos | E35: =IFERROR(__xludf.DUMMYFUNCTION("""COMPUTED_VALUE"""),"https://docs.fivem.net/vehicles/weevil.webp") -> https://docs.fivem.net/vehicles/weevil.webp
A36: =IFERROR(__xludf.DUMMYFUNCTION("""COMPUTED_VALUE"""),"broadway") -> broadway | B36: =IFERROR(__xludf.DUMMYFUNCTION("""COMPUTED_VALUE"""),"Broadway") -> Broadway | C36: =IFERROR(__xludf.DUMMYFUNCTION("""COMPUTED_VALUE"""),29000.0) -> 29000 | D36: =IFERROR(__xludf.DUMMYFUNCTION("""COMPUTED_VALUE"""),"Coupes") -> Coupes | E36: =IFERROR(__xludf.DUMMYFUNCTION("""COMPUTED_VALUE"""),"https://docs.fivem.net/vehicles/broadway.webp") -> https://docs.fivem.net/vehicles/broadway.webp
A37: =IFERROR(__xludf.DUMMYFUNCTION("""COMPUTED_VALUE"""),"champion") -> champion | B37: =IFERROR(__xludf.DUMMYFUNCTION("""COMPUTED_VALUE"""),"Champion") -> Champion | C37: =IFERROR(__xludf.DUMMYFUNCTION("""COMPUTED_VALUE"""),125000.0) -> 125000 | D37: =IFERROR(__xludf.DUMMYFUNCTION("""COMPUTED_VALUE"""),"Coupes") -> Coupes | E37: =IFERROR(__xludf.DUMMYFUNCTION("""COMPUTED_VALUE"""),"https://docs.fivem.net/vehicles/champion.webp") -> https://docs.fivem.net/vehicles/champion.webp
A38: =IFERROR(__xludf.DUMMYFUNCTION("""COMPUTED_VALUE"""),"cogcabrio") -> cogcabrio | B38: =IFERROR(__xludf.DUMMYFUNCTION("""COMPUTED_VALUE"""),"Cognoscenti Cabrio") -> Cognoscenti Cabrio | C38: =IFERROR(__xludf.DUMMYFUNCTION("""COMPUTED_VALUE"""),14000.0) -> 14000 | D38: =IFERROR(__xludf.DUMMYFUNCTION("""COMPUTED_VALUE"""),"Coupes") -> Coupes | E38: =IFERROR(__xludf.DUMMYFUNCTION("""COMPUTED_VALUE"""),"https://docs.fivem.net/vehicles/cogcabrio.webp") -> https://docs.fivem.net/vehicles/cogcabrio.webp
A39: =IFERROR(__xludf.DUMMYFUNCTION("""COMPUTED_VALUE"""),"cognoscenti") -> cognoscenti | B39: =IFERROR(__xludf.DUMMYFUNCTION("""COMPUTED_VALUE"""),"Cognoscenti") -> Cognoscenti | C39: =IFERROR(__xludf.DUMMYFUNCTION("""COMPUTED_VALUE"""),12000.0) -> 12000 | D39: =IFERROR(__xludf.DUMMYFUNCTION("""COMPUTED_VALUE"""),"Coupes") -> Coupes | E39: =IFERROR(__xludf.DUMMYFUNCTION("""COMPUTED_VALUE"""),"https://docs.fivem.net/vehicles/cognoscenti.webp") -> https://docs.fivem.net/vehicles/cognoscenti.webp
A40: =IFERROR(__xludf.DUMMYFUNCTION("""COMPUTED_VALUE"""),"exemplar") -> exemplar | B40: =IFERROR(__xludf.DUMMYFUNCTION("""COMPUTED_VALUE"""),"Exemplar") -> Exemplar | C40: =IFERROR(__xludf.DUMMYFUNCTION("""COMPUTED_VALUE"""),40000.0) -> 40000 | D40: =IFERROR(__xludf.DUMMYFUNCTION("""COMPUTED_VALUE"""),"Coupes") -> Coupes | E40: =IFERROR(__xludf.DUMMYFUNCTION("""COMPUTED_VALUE"""),"https://docs.fivem.net/vehicles/exemplar.webp") -> https://docs.fivem.net/vehicles/exemplar.webp
...
